Workbook

Sheet Combatant Information
B2: Round | C2: Combatants | D2: Degree | E2: Rank | F2: Path | G2: Current Stamina | H2: Stance | I2: Energy Segments
B3: =Input!B18 -> 1 | C3: =Input!A3 -> Will | D3: =Input!B3 -> 1st | E3: =Input!C3 -> Stone | F3: =Input!D3 -> Air | G3: =Math!C13 -> 25 | H3: ='Combatant info data'!AM9 | I3: ='Combatant info data'!AN9 -> 0 | J3: ='Combatant info data'!AO9 -> 0 | K3: ='Combatant info data'!AP9 -> 0 | L3: ='Combatant info data'!AQ9 -> 0 | M3: ='Combatant info data'!AR9 -> 0 | N3: ='Combatant info data'!AS9 -> 0 | O3: ='Combatant info data'!AT3 -> 1
C4: =Input!A4 -> Carter | F4: =Input!D4 -> Earth | G4: =Math!C14 -> 25 | H4: ='Combatant info data'!AM10 | I4: ='Combatant info data'!AN10 -> 0 | J4: ='Combatant info data'!AO10 -> 0 | K4: ='Combatant info data'!AP10 -> 0 | L4: ='Combatant info data'!AQ10 -> 0 | M4: ='Combatant info data'!AR10 -> 0 | N4: ='Combatant info data'!AS10 -> 0 | O4: ='Combatant info data'!AT4 -> 1
C5: =Input!A5 -> Joe | F5: =Input!D5 -> Shadow | G5: =Math!C15 -> 25 | H5: ='Combatant info data'!AM11 | I5: ='Combatant info data'!AN11 -> 0 | J5: ='Combatant info data'!AO11 -> 0 | K5: ='Combatant info data'!AP11 -> 0 | L5: ='Combatant info data'!AQ11 -> 0 | M5: ='Combatant info data'!AR11 -> 0 | N5: ='Combatant info data'!AS11 -> 0 | O5: ='Combatant info data'!AT5 -> 1
C6: =Input!A6 -> Jake | D6: =Input!B6 -> 1st | E6: =Input!C6 -> Stone | F6: =Input!D6 -> Earth | G6: ='Combatant info data'!AM3 -> 1 | H6: ='Combatant info data'!AM12 | I6: ='Combatant info data'!AN12 -> 0 | J6: ='Combatant info data'!AO12 -> 0 | K6: ='Combatant info data'!AP12 -> 0 | L6: ='Combatant info data'!AQ12 -> 0 | M6: ='Combatant info data'!AR12 -> 0 | N6: ='Combatant info data'!AS12 -> 0
C7: =Input!A7 -> Jim | F7: =Input!D7 -> Earth | G7: ='Combatant info data'!AM4 -> 1 | H7: ='Combatant info data'!AM13 | I7: ='Combatant info data'!AN13 -> 0 | J7: ='Combatant info data'!AO13 -> 0 | K7: ='Combatant info data'!AP13 -> 0 | L7: ='Combatant info data'!AQ13 -> 0 | M7: ='Combatant info data'!AR13 -> 0 | N7: ='Combatant info data'!AS13 -> 0
C8: =Input!A8 -> Jordan | F8: =Input!D8 -> Earth | G8: ='Combatant info data'!AM5 -> 1 | H8: ='Combatant info data'!AM14 | I8: ='Combatant info data'!AN14 -> 0 | J8: ='Combatant info data'!AO14 -> 0 | K8: ='Combatant info data'!AP14 -> 0 | L8: ='Combatant info data'!AQ14 -> 0 | M8: ='Combatant info data'!AR14 -> 0 | N8: ='Combatant info data'!AS14 -> 0
B10: Actions - Round Prep Phase
B11: Attack | C11: Attacks a target
B12: Defend | C12: Choose an ally to defend for the round, has to be an ally not defending or being defended
B13: Evade | C13: Attempts to carefully move around the opponents to recover stamina
B14: Special | C14: Fueled by energy, mostly based off the chosen path
B16: Reactions - Round Execution Phase
B17: Block | C17: Mitigate damage based on proficiency
B18: Dodge | C18: Attempt to avoid incoming attack, failure mitigates some damage
B19: Parry | C19: Attempts to negate an incoming attack and respond with a counter attack, failure mitigates no damage
B21: Combat Rolls
B22: Speed | C22: Determines action speed
B23: Rank | C23: Chance to instant KO opponent. Triggered when you are at least one rank above an opponent
B24: Blindside | C24: If the action speed is at least twice as fast as the target’s base speed, there is a chance that the action can’t be defended
B25: Defense | C25: Used to check for success in defense reaction
B26: Crushing Blow | C26: Chance to overpower the target and make future blocking less effective
B28: Paths
B29: Path | C29: =Paths!L1 -> Style Focus | D29: =Paths!M1 -> Energy Focus | E29: Focus Statement
B30: Fire | C30: =Paths!L2 -> Reaction | D30: =Paths!M2 -> Parry Success Rate | E30: Focuses inward, improving the chance to successfully parry an attack.
B31: Water | C31: =Paths!L3 -> Action | D31: =Paths!M3 -> Dodge Success Rate | E31: Focuses outward, reducing the chance to successfully dodge an attack.
B32: Air | C32: =Paths!L4 -> Reaction | D32: =Paths!M4 -> Dodge Success Rate | E32: Focuses inward, improving the chance to successfully dodge an attack.
B33: Earth | C33: =Paths!L5 -> Action | D33: =Paths!M5 -> Block Success Rate | E33: Focuses outward, reducing the chance to successfully block an attack.
B34: Shadow | C34: =Paths!L6 -> Action | D34: =Paths!M6 -> Parry Success Rate | E34: Focuses outward, reducing the chance to successfully parry an attack.
B35: Light | C35: =Paths!L7 -> Reaction | D35: =Paths!M7 -> Block Success Rate | E35: Focuses inward, improving the chance to successfully block an attack.

Sheet Character Sheet - P1
B2: Character Info | K2: Reaction Skills | V2: Path Information
C4: Name | E4: Degree | G4: Rank | L4: Block | W4: Air | X4: =VLOOKUP(W4,Paths!$K$2:$N$7,4,FALSE) -> Focuses inward, improving the chance to successfully dodge an attack.
C5: Will | E5: ='Combatant Information'!D3 -> 1st | G5: ='Combatant Information'!E3 -> Stone | L5: Rank | M5: XP | N5: Next Rank | O5: Success Rate | P5: Successful Damage Mitigation | R5: Unsuccessful Damage Mitigation
C6: Team Name | E6: =Input!I11 -> The Barrels | L6: =IF(M6>='Reaction Progression & Log'!$B$12,'Reaction Progression & Log'!$A$12,IF(M6>='Reaction Progression & Log'!$B$11,'Reaction Progression & Log'!$A$11,IF(M6>='Reaction Progression & Log'!$B$10,'Reaction Progression & Log'!$A$10,IF(M6>='Reaction Progression & Log'!$B$9,'Reaction Progression & Log'!$A$9,IF(M6>='Reaction Progression & Log'!$B$8,'Reaction Progression & Log'!$A$8,IF(M6>='Reaction Progression & Log'!$B$7,'Reaction Progression & Log'!$A$7,IF(M6>='Reaction Progression & Log'!$B$6,'Reaction Progression & Log'!$A$6,IF(M6>='Reaction Progression & Log'!$B$5,'Reaction Progression & Log'!$A$5,IF(M6>='Reaction Progression & Log'!$B$4,'Reaction Progression & Log'!$A$4,IF(M6>='Reaction Progression & Log'!$B$3,'Reaction Progression & Log'!$A$3,'Reaction Progression & Log'!$A$2)))))))))) -> 1 | M6: =SUMIF('Reaction Progression & Log'!$D:$D,$C$5,'Reaction Progression & Log'!$E:$E) -> 6 | N6: =IF(L6=11,"--",VLOOKUP(L6+1,'Reaction Progression & Log'!$A$2:$B$12,2,FALSE)) -> 100 | O6: =VLOOKUP($L6,'Defense Simulations'!$C$3:$W$13,3,FALSE) -> 0.4 | P6: =VLOOKUP($L6,'Defense Simulations'!$C$3:$W$13,4,FALSE) -> 0.55 | R6: =VLOOKUP($L6,'Defense Simulations'!$C$3:$W$13,5,FALSE) -> 0.4 | X6: Fire | Y6: Water | Z6: Air | AA6: Earth | AB6: Shadow | AC6: Light
L7: Current | O7: =Math!J13 -> 0.4 | P7: =Math!L13 -> 0.55 | R7: =Math!N13 -> 0.4
W8: Attunement
B9: Core Training Attributes | L9: Dodge | W9: Selection | X9: FALSE | Y9: FALSE | Z9: TRUE | AA9: FALSE | AB9: FALSE | AC9: FALSE
L10: Rank | M10: XP | N10: Next Rank | O10: Success Rate | P10: Successful Damage Mitigation | R10: Unsuccessful Damage Mitigation | X10: =IF(X9=TRUE,X6,"") | Y10: =IF(Y9=TRUE,Y6,"") | Z10: =IF(Z9=TRUE,Z6,"") -> Air | AA10: =IF(AA9=TRUE,AA6,"") | AB10: =IF(AB9=TRUE,AB6,"") | AC10: =IF(AC9=TRUE,AC6,"")
D11: Available CT Points | F11: Stamina | G11: Power | H11: Speed | L11: =IF(M11>='Reaction Progression & Log'!$B$12,'Reaction Progression & Log'!$A$12,IF(M11>='Reaction Progression & Log'!$B$11,'Reaction Progression & Log'!$A$11,IF(M11>='Reaction Progression & Log'!$B$10,'Reaction Progression & Log'!$A$10,IF(M11>='Reaction Progression & Log'!$B$9,'Reaction Progression & Log'!$A$9,IF(M11>='Reaction Progression & Log'!$B$8,'Reaction Progression & Log'!$A$8,IF(M11>='Reaction Progression & Log'!$B$7,'Reaction Progression & Log'!$A$7,IF(M11>='Reaction Progression & Log'!$B$6,'Reaction Progression & Log'!$A$6,IF(M11>='Reaction Progression & Log'!$B$5,'Reaction Progression & Log'!$A$5,IF(M11>='Reaction Progression & Log'!$B$4,'Reaction Progression & Log'!$A$4,IF(M11>='Reaction Progression & Log'!$B$3,'Reaction Progression & Log'!$A$3,'Reaction Progression & Log'!$A$2)))))))))) -> 1 | M11: =SUMIF('Reaction Progression & Log'!$D:$D,$C$5,'Reaction Progression & Log'!$F:$F) -> 8 | N11: =IF(L11=11,"--",VLOOKUP(L11+1,'Reaction Progression & Log'!$A$2:$B$12,2,FALSE)) -> 100 | O11: =VLOOKUP($L11,'Defense Simulations'!$C$3:$W$13,11,FALSE) -> 0.3 | P11: =VLOOKUP($L11,'Defense Simulations'!$C$3:$W$13,12,FALSE) -> 0.8 | R11: =VLOOKUP($L11,'Defense Simulations'!$C$3:$W$13,13,FALSE) -> 0.1 | W11: Progression
C12: Baseline | D12: =VLOOKUP(CONCATENATE(E5," Degree ",G5),'Rank Progression'!C:G,3,FALSE)-(F13+G13+H13) -> 0 | F12: 5 | G12: 5 | H12: 5 | L12: Current | O12: =Math!P13 -> 0.3 | P12: =Math!R13 -> 0.8 | R12: =Math!T13 -> 0.1 | W12: Energy Accumulation | X12: =CONCATENATE(Paths!AE3," / ",VLOOKUP(X13+1,Paths!$P$2:$S$6,2,FALSE)) -> 0 / 35 | Y12: =CONCATENATE(Paths!AG3," / ",VLOOKUP(Y13+1,Paths!$P$2:$S$6,2,FALSE)) -> 0 / 35 | Z12: =CONCATENATE(Paths!AI3," / ",VLOOKUP(Z13+1,Paths!$P$2:$S$6,2,FALSE)) -> 9.5 / 35 | AA12: =CONCATENATE(Paths!AK3," / ",VLOOKUP(AA13+1,Paths!$P$2:$S$6,2,FALSE)) -> 1.25 / 35 | AB12: =CONCATENATE(Paths!AM3," / ",VLOOKUP(AB13+1,Paths!$P$2:$S$6,2,FALSE)) -> 0 / 35 | AC12: =CONCATENATE(Paths!AO3," / ",VLOOKUP(AC13+1,Paths!$P$2:$S$6,2,FALSE)) -> 0 / 35
C13: CT Points | W13: Ascension Gems | X13: =Paths!AF3 -> 0 | Y13: =Paths!AH3 -> 0 | Z13: =Paths!AJ3 -> 0 | AA13: =Paths!AL3 -> 0 | AB13: =Paths!AN3 -> 0 | AC13: =Paths!AP3 -> 0
C14: Current | F14: =F12+F13 -> 5 | G14: =G12+G13 -> 5 | H14: =H12+H13 -> 5 | L14: Parry
L15: Rank | M15: XP | N15: Next Rank | O15: Success Rate | P15: Successful Damage Mitigation | R15: Unsuccessful Damage Mitigation | W15: Style
L16: =IF(M16>='Reaction Progression & Log'!$B$12,'Reaction Progression & Log'!$A$12,IF(M16>='Reaction Progression & Log'!$B$11,'Reaction Progression & Log'!$A$11,IF(M16>='Reaction Progression & Log'!$B$10,'Reaction Progression & Log'!$A$10,IF(M16>='Reaction Progression & Log'!$B$9,'Reaction Progression & Log'!$A$9,IF(M16>='Reaction Progression & Log'!$B$8,'Reaction Progression & Log'!$A$8,IF(M16>='Reaction Progression & Log'!$B$7,'Reaction Progression & Log'!$A$7,IF(M16>='Reaction Progression & Log'!$B$6,'Reaction Progression & Log'!$A$6,IF(M16>='Reaction Progression & Log'!$B$5,'Reaction Progression & Log'!$A$5,IF(M16>='Reaction Progression & Log'!$B$4,'Reaction Progression & Log'!$A$4,IF(M16>='Reaction Progression & Log'!$B$3,'Reaction Progression & Log'!$A$3,'Reaction Progression & Log'!$A$2)))))))))) -> 1 | M16: =SUMIF('Reaction Progression & Log'!$D:$D,$C$5,'Reaction Progression & Log'!$G:$G) -> 10 | N16: =IF(L16=11,"--",VLOOKUP(L16+1,'Reaction Progression & Log'!$A$2:$B$12,2,FALSE)) -> 100 | O16: =VLOOKUP($L16,'Defense Simulations'!$C$3:$W$13,19,FALSE) -> 0.1 | P16: =VLOOKUP($L16,'Defense Simulations'!$C$3:$W$13,20,FALSE) -> 0.9 | R16: =VLOOKUP($L16,'Defense Simulations'!$C$3:$W$13,21,FALSE) -> 0 | W16: Style Focus | X16: Reaction | Y16: Action | Z16: Reaction | AA16: Action | AB16: Action | AC16: Reaction
B17: Personality | L17: Current | O17: =Math!V13 -> 0.1 | P17: =Math!X13 -> 0.9 | R17: =Math!Z13 -> 0 | W17: Energy Focus | X17: Parry S.R. | Y17: Dodge S.R. | Z17: Dodge S.R. | AA17: Block S.R. | AB17: Parry S.R. | AC17: Block S.R.
C19: =Personality!B3 -> Patience | D19: =Personality!C3 -> Empathy | E19: =Personality!D3 -> Cunning | F19: =Personality!E3 -> Logic | G19: =Personality!F3 -> Kindness | H19: =Personality!G3 -> Charisma | W19: Segment Bonuses
C20: =Personality!B4 -> 0.15 | D20: =Personality!C4 -> 0.15 | E20: =Personality!D4 -> 0.19 | F20: =Personality!E4 -> 0.16 | G20: =Personality!F4 -> 0.16 | H20: =Personality!G4 -> 0.19 | K20: Buffs / Debuffs | W20: 1st Segment Bonus | X20: =VLOOKUP(CONCATENATE(X$6," - ",X$13),Paths!$C$2:$I$28,2,FALSE) -> 0.04 | Y20: =VLOOKUP(CONCATENATE(Y6," - ",Y13),Paths!$C$2:$I$28,2,FALSE) -> -0.06 | Z20: =VLOOKUP(CONCATENATE(Z6," - ",Z13),Paths!$C$2:$I$28,2,FALSE) -> 0.06 | AA20: =VLOOKUP(CONCATENATE(AA6," - ",AA13),Paths!$C$2:$I$28,2,FALSE) -> -0.08 | AB20: =VLOOKUP(CONCATENATE(AB6," - ",AB13),Paths!$C$2:$I$28,2,FALSE) -> -0.04 | AC20: =VLOOKUP(CONCATENATE(AC6," - ",AC13),Paths!$C$2:$I$28,2,FALSE) -> 0.08
W21: 2nd Segment Bonus | X21: =VLOOKUP(CONCATENATE(X$6," - ",X$13),Paths!$C$2:$I$28,3,FALSE) -> 0.05 | Y21: =VLOOKUP(CONCATENATE(Y$6," - ",Y$13),Paths!$C$2:$I$28,3,FALSE) -> -0.07 | Z21: =VLOOKUP(CONCATENATE(Z$6," - ",Z$13),Paths!$C$2:$I$28,3,FALSE) -> 0.07 | AA21: =VLOOKUP(CONCATENATE(AA$6," - ",AA$13),Paths!$C$2:$I$28,3,FALSE) -> -0.09 | AB21: =VLOOKUP(CONCATENATE(AB$6," - ",AB$13),Paths!$C$2:$I$28,3,FALSE) -> -0.05 | AC21: =VLOOKUP(CONCATENATE(AC$6," - ",AC$13),Paths!$C$2:$I$28,3,FALSE) -> 0.09
L22: Source | N22: Type | Q22: Round Start | R22: Round End | S22: Change | W22: 3rd Segment Bonus | X22: =VLOOKUP(CONCATENATE(X$6," - ",X$13),Paths!$C$2:$I$28,4,FALSE) -> 0.06 | Y22: =VLOOKUP(CONCATENATE(Y$6," - ",Y$13),Paths!$C$2:$I$28,4,FALSE) -> -0.08 | Z22: =VLOOKUP(CONCATENATE(Z$6," - ",Z$13),Paths!$C$2:$I$28,4,FALSE) -> 0.08 | AA22: =VLOOKUP(CONCATENATE(AA$6," - ",AA$13),Paths!$C$2:$I$28,4,FALSE) -> -0.1 | AB22: =VLOOKUP(CONCATENATE(AB$6," - ",AB$13),Paths!$C$2:$I$28,4,FALSE) -> -0.06 | AC22: =VLOOKUP(CONCATENATE(AC$6," - ",AC$13),Paths!$C$2:$I$28,4,FALSE) -> 0.1
L23: ='Combatant info data'!L6 | N23: ='Combatant info data'!M6 | Q23: ='Combatant info data'!N6 | R23: ='Combatant info data'!O6 | S23: ='Combatant info data'!P6 | W23: 4th Segment Bonus | X23: =VLOOKUP(CONCATENATE(X$6," - ",X$13),Paths!$C$2:$I$28,5,FALSE) -> 0.07 | Y23: =VLOOKUP(CONCATENATE(Y$6," - ",Y$13),Paths!$C$2:$I$28,5,FALSE) -> -0.09 | Z23: =VLOOKUP(CONCATENATE(Z$6," - ",Z$13),Paths!$C$2:$I$28,5,FALSE) -> 0.09 | AA23: =VLOOKUP(CONCATENATE(AA$6," - ",AA$13),Paths!$C$2:$I$28,5,FALSE) -> -0.11 | AB23: =VLOOKUP(CONCATENATE(AB$6," - ",AB$13),Paths!$C$2:$I$28,5,FALSE) -> -0.07 | AC23: =VLOOKUP(CONCATENATE(AC$6," - ",AC$13),Paths!$C$2:$I$28,5,FALSE) -> 0.11
L24: ='Combatant info data'!L7 | N24: ='Combatant info data'!M7 | Q24: ='Combatant info data'!N7 | R24: ='Combatant info data'!O7 | S24: ='Combatant info data'!P7 | W24: 5th Segment Bonus | X24: =VLOOKUP(CONCATENATE(X$6," - ",X$13),Paths!$C$2:$I$28,6,FALSE) -> 0.08 | Y24: =VLOOKUP(CONCATENATE(Y$6," - ",Y$13),Paths!$C$2:$I$28,6,FALSE) -> -0.1 | Z24: =VLOOKUP(CONCATENATE(Z$6," - ",Z$13),Paths!$C$2:$I$28,6,FALSE) -> 0.1 | AA24: =VLOOKUP(CONCATENATE(AA$6," - ",AA$13),Paths!$C$2:$I$28,6,FALSE) -> -0.12 | AB24: =VLOOKUP(CONCATENATE(AB$6," - ",AB$13),Paths!$C$2:$I$28,6,FALSE) -> -0.08 | AC24: =VLOOKUP(CONCATENATE(AC$6," - ",AC$13),Paths!$C$2:$I$28,6,FALSE) -> 0.12
L25: ='Combatant info data'!L8 | N25: ='Combatant info data'!M8 | Q25: ='Combatant info data'!N8 | R25: ='Combatant info data'!O8 | S25: ='Combatant info data'!P8 | W25: 6th Segment Bonus | X25: =VLOOKUP(CONCATENATE(X$6," - ",X$13),Paths!$C$2:$I$28,7,FALSE) -> 0.09 | Y25: =VLOOKUP(CONCATENATE(Y$6," - ",Y$13),Paths!$C$2:$I$28,7,FALSE) -> -0.11 | Z25: =VLOOKUP(CONCATENATE(Z$6," - ",Z$13),Paths!$C$2:$I$28,7,FALSE) -> 0.11 | AA25: =VLOOKUP(CONCATENATE(AA$6," - ",AA$13),Paths!$C$2:$I$28,7,FALSE) -> -0.13 | AB25: =VLOOKUP(CONCATENATE(AB$6," - ",AB$13),Paths!$C$2:$I$28,7,FALSE) -> -0.09 | AC25: =VLOOKUP(CONCATENATE(AC$6," - ",AC$13),Paths!$C$2:$I$28,7,FALSE) -> 0.13
L26: ='Combatant info data'!L9 | N26: ='Combatant info data'!M9 | Q26: ='Combatant info data'!N9 | R26: ='Combatant info data'!O9 | S26: ='Combatant info data'!P9
L27: ='Combatant info data'!L10 | N27: ='Combatant info data'!M10 | Q27: ='Combatant info data'!N10 | R27: ='Combatant info data'!O10 | S27: ='Combatant info data'!P10 | W27: Other Bonuses
L28: ='Combatant info data'!L11 | N28: ='Combatant info data'!M11 | Q28: ='Combatant info data'!N11 | R28: ='Combatant info data'!O11 | S28: ='Combatant info data'!P11 | W28: Energy Accumulation Bonus | X28: =VLOOKUP(X13,Paths!$P$2:$S$5,3,FALSE) -> 0 | Y28: =VLOOKUP(Y13,Paths!$P$2:$S$5,3,FALSE) -> 0 | Z28: =VLOOKUP(Z13,Paths!$P$2:$S$5,3,FALSE) -> 0 | AA28: =VLOOKUP(AA13,Paths!$P$2:$S$5,3,FALSE) -> 0 | AB28: =VLOOKUP(AB13,Paths!$P$2:$S$5,3,FALSE) -> 0 | AC28: =VLOOKUP(AC13,Paths!$P$2:$S$5,3,FALSE) -> 0
L29: ='Combatant info data'!L12 | N29: ='Combatant info data'!M12 | Q29: ='Combatant info data'!N12 | R29: ='Combatant info data'!O12 | S29: ='Combatant info data'!P12 | W29: Starting Energy Segements | X29: =VLOOKUP(X13,Paths!$P$2:$S$5,4,FALSE) -> 0 | Y29: =VLOOKUP(Y13,Paths!$P$2:$S$5,4,FALSE) -> 0 | Z29: =VLOOKUP(Z13,Paths!$P$2:$S$5,4,FALSE) -> 0 | AA29: =VLOOKUP(AA13,Paths!$P$2:$S$5,4,FALSE) -> 0 | AB29: =VLOOKUP(AB13,Paths!$P$2:$S$5,4,FALSE) -> 0 | AC29: =VLOOKUP(AC13,Paths!$P$2:$S$5,4,FALSE) -> 0
W31: Prime Special
W32: Segment Requirements | Y32: Result
W33: Minimum | X33: Maximum | Y33: Power Amplification | AB33: Defense Constraint
W34: =VLOOKUP(W4,'Special Techniques'!$A$2:$E$7,4,FALSE) -> 1 | X34: =VLOOKUP(W4,'Special Techniques'!$A$2:$E$7,5,FALSE) -> 5 | Y34: +10% per segment used | AB34: =VLOOKUP(W4,'Special Techniques'!A2:H7,7,FALSE) -> Dodge

Sheet Character Sheet - P2
B2: Character Info | K2: Reaction Skills | V2: Path Information
C4: Name | E4: Degree | G4: Rank | L4: Block | W4: Earth | X4: =VLOOKUP(W4,Paths!$K$2:$N$7,4,FALSE) -> Focuses outward, reducing the chance to successfully block an attack.
C5: Carter | E5: ='Combatant Information'!D3 -> 1st | G5: ='Combatant Information'!E3 -> Stone | L5: Rank | M5: XP | N5: Next Rank | O5: Success Rate | P5: Successful Damage Mitigation | R5: Unsuccessful Damage Mitigation
C6: Team Name | E6: =Input!I11 -> The Barrels | L6: =IF(M6>='Reaction Progression & Log'!$B$12,'Reaction Progression & Log'!$A$12,IF(M6>='Reaction Progression & Log'!$B$11,'Reaction Progression & Log'!$A$11,IF(M6>='Reaction Progression & Log'!$B$10,'Reaction Progression & Log'!$A$10,IF(M6>='Reaction Progression & Log'!$B$9,'Reaction Progression & Log'!$A$9,IF(M6>='Reaction Progression & Log'!$B$8,'Reaction Progression & Log'!$A$8,IF(M6>='Reaction Progression & Log'!$B$7,'Reaction Progression & Log'!$A$7,IF(M6>='Reaction Progression & Log'!$B$6,'Reaction Progression & Log'!$A$6,IF(M6>='Reaction Progression & Log'!$B$5,'Reaction Progression & Log'!$A$5,IF(M6>='Reaction Progression & Log'!$B$4,'Reaction Progression & Log'!$A$4,IF(M6>='Reaction Progression & Log'!$B$3,'Reaction Progression & Log'!$A$3,'Reaction Progression & Log'!$A$2)))))))))) -> 1 | M6: =SUMIF('Reaction Progression & Log'!$D:$D,$C$5,'Reaction Progression & Log'!$E:$E) -> 8 | N6: =IF(L6=11,"--",VLOOKUP(L6+1,'Reaction Progression & Log'!$A$2:$B$12,2,FALSE)) -> 100 | O6: =VLOOKUP($L6,'Defense Simulations'!$C$3:$W$13,3,FALSE) -> 0.4 | P6: =VLOOKUP($L6,'Defense Simulations'!$C$3:$W$13,4,FALSE) -> 0.55 | R6: =VLOOKUP($L6,'Defense Simulations'!$C$3:$W$13,5,FALSE) -> 0.4 | X6: Fire | Y6: Water | Z6: Air | AA6: Earth | AB6: Shadow | AC6: Light
L7: Current | O7: =Math!J14 -> 0.4 | P7: =Math!L14 -> 0.55 | R7: =Math!N14 -> 0.4
W8: Attunement
B9: Core Training Attributes | L9: Dodge | W9: Selection | X9: FALSE | Y9: FALSE | Z9: FALSE | AA9: TRUE | AB9: FALSE | AC9: FALSE
L10: Rank | M10: XP | N10: Next Rank | O10: Success Rate | P10: Successful Damage Mitigation | R10: Unsuccessful Damage Mitigation | X10: =IF(X9=TRUE,X6,"") | Y10: =IF(Y9=TRUE,Y6,"") | Z10: =IF(Z9=TRUE,Z6,"") | AA10: =IF(AA9=TRUE,AA6,"") -> Earth | AB10: =IF(AB9=TRUE,AB6,"") | AC10: =IF(AC9=TRUE,AC6,"")
D11: Available CT Points | F11: Stamina | G11: Power | H11: Speed | L11: =IF(M11>='Reaction Progression & Log'!$B$12,'Reaction Progression & Log'!$A$12,IF(M11>='Reaction Progression & Log'!$B$11,'Reaction Progression & Log'!$A$11,IF(M11>='Reaction Progression & Log'!$B$10,'Reaction Progression & Log'!$A$10,IF(M11>='Reaction Progression & Log'!$B$9,'Reaction Progression & Log'!$A$9,IF(M11>='Reaction Progression & Log'!$B$8,'Reaction Progression & Log'!$A$8,IF(M11>='Reaction Progression & Log'!$B$7,'Reaction Progression & Log'!$A$7,IF(M11>='Reaction Progression & Log'!$B$6,'Reaction Progression & Log'!$A$6,IF(M11>='Reaction Progression & Log'!$B$5,'Reaction Progression & Log'!$A$5,IF(M11>='Reaction Progression & Log'!$B$4,'Reaction Progression & Log'!$A$4,IF(M11>='Reaction Progression & Log'!$B$3,'Reaction Progression & Log'!$A$3,'Reaction Progression & Log'!$A$2)))))))))) -> 1 | M11: =SUMIF('Reaction Progression & Log'!$D:$D,$C$5,'Reaction Progression & Log'!$F:$F) -> 4 | N11: =IF(L11=11,"--",VLOOKUP(L11+1,'Reaction Progression & Log'!$A$2:$B$12,2,FALSE)) -> 100 | O11: =VLOOKUP($L11,'Defense Simulations'!$C$3:$W$13,11,FALSE) -> 0.3 | P11: =VLOOKUP($L11,'Defense Simulations'!$C$3:$W$13,12,FALSE) -> 0.8 | R11: =VLOOKUP($L11,'Defense Simulations'!$C$3:$W$13,13,FALSE) -> 0.1 | W11: Progression
C12: Baseline | D12: =VLOOKUP(CONCATENATE(E5," Degree ",G5),'Rank Progression'!C:G,3,FALSE)-(F13+G13+H13) -> 0 | F12: 5 | G12: 5 | H12: 5 | L12: Current | O12: =Math!P14 -> 0.3 | P12: =Math!R14 -> 0.8 | R12: =Math!T14 -> 0.1 | W12: Energy Accumulation | X12: =CONCATENATE(Paths!AE4," / ",VLOOKUP(X13+1,Paths!$P$2:$S$6,2,FALSE)) -> 0.5 / 35 | Y12: =CONCATENATE(Paths!AG4," / ",VLOOKUP(Y13+1,Paths!$P$2:$S$6,2,FALSE)) -> 0 / 35 | Z12: =CONCATENATE(Paths!AI4," / ",VLOOKUP(Z13+1,Paths!$P$2:$S$6,2,FALSE)) -> 1 / 35 | AA12: =CONCATENATE(Paths!AK4," / ",VLOOKUP(AA13+1,Paths!$P$2:$S$6,2,FALSE)) -> 5.5 / 35 | AB12: =CONCATENATE(Paths!AM4," / ",VLOOKUP(AB13+1,Paths!$P$2:$S$6,2,FALSE)) -> 3.5 / 35 | AC12: =CONCATENATE(Paths!AO4," / ",VLOOKUP(AC13+1,Paths!$P$2:$S$6,2,FALSE)) -> 0 / 35
C13: CT Points | W13: Ascension Gems | X13: =Paths!AF4 -> 0 | Y13: =Paths!AH4 -> 0 | Z13: =Paths!AJ4 -> 0 | AA13: =Paths!AL4 -> 0 | AB13: =Paths!AN4 -> 0 | AC13: =Paths!AP4 -> 0
C14: Current | F14: =F12+F13 -> 5 | G14: =G12+G13 -> 5 | H14: =H12+H13 -> 5 | L14: Parry
L15: Rank | M15: XP | N15: Next Rank | O15: Success Rate | P15: Successful Damage Mitigation | R15: Unsuccessful Damage Mitigation | W15: Style
L16: =IF(M16>='Reaction Progression & Log'!$B$12,'Reaction Progression & Log'!$A$12,IF(M16>='Reaction Progression & Log'!$B$11,'Reaction Progression & Log'!$A$11,IF(M16>='Reaction Progression & Log'!$B$10,'Reaction Progression & Log'!$A$10,IF(M16>='Reaction Progression & Log'!$B$9,'Reaction Progression & Log'!$A$9,IF(M16>='Reaction Progression & Log'!$B$8,'Reaction Progression & Log'!$A$8,IF(M16>='Reaction Progression & Log'!$B$7,'Reaction Progression & Log'!$A$7,IF(M16>='Reaction Progression & Log'!$B$6,'Reaction Progression & Log'!$A$6,IF(M16>='Reaction Progression & Log'!$B$5,'Reaction Progression & Log'!$A$5,IF(M16>='Reaction Progression & Log'!$B$4,'Reaction Progression & Log'!$A$4,IF(M16>='Reaction Progression & Log'!$B$3,'Reaction Progression & Log'!$A$3,'Reaction Progression & Log'!$A$2)))))))))) -> 1 | M16: =SUMIF('Reaction Progression & Log'!$D:$D,$C$5,'Reaction Progression & Log'!$G:$G) -> 4 | N16: =IF(L16=11,"--",VLOOKUP(L16+1,'Reaction Progression & Log'!$A$2:$B$12,2,FALSE)) -> 100 | O16: =VLOOKUP($L16,'Defense Simulations'!$C$3:$W$13,19,FALSE) -> 0.1 | P16: =VLOOKUP($L16,'Defense Simulations'!$C$3:$W$13,20,FALSE) -> 0.9 | R16: =VLOOKUP($L16,'Defense Simulations'!$C$3:$W$13,21,FALSE) -> 0 | W16: Style Focus | X16: Reaction | Y16: Action | Z16: Reaction | AA16: Action | AB16: Action | AC16: Reaction
B17: Personality | L17: Current | O17: =Math!V14 -> 0.1 | P17: =Math!X14 -> 0.9 | R17: =Math!Z14 -> 0 | W17: Energy Focus | X17: Parry S.R. | Y17: Dodge S.R. | Z17: Dodge S.R. | AA17: Block S.R. | AB17: Parry S.R. | AC17: Block S.R.
C19: =Personality!B3 -> Patience | D19: =Personality!C3 -> Empathy | E19: =Personality!D3 -> Cunning | F19: =Personality!E3 -> Logic | G19: =Personality!F3 -> Kindness | H19: =Personality!G3 -> Charisma | W19: Segment Bonuses
C20: =Personality!B5 -> 0.15 | D20: =Personality!C5 -> 0.19 | E20: =Personality!D5 -> 0.15 | F20: =Personality!E5 -> 0.19 | G20: =Personality!F5 -> 0.16 | H20: =Personality!G5 -> 0.16 | K20: Buffs / Debuffs | W20: 1st Segment Bonus | X20: =VLOOKUP(CONCATENATE(X$6," - ",X$13),Paths!$C$2:$I$28,2,FALSE) -> 0.04 | Y20: =VLOOKUP(CONCATENATE(Y6," - ",Y13),Paths!$C$2:$I$28,2,FALSE) -> -0.06 | Z20: =VLOOKUP(CONCATENATE(Z6," - ",Z13),Paths!$C$2:$I$28,2,FALSE) -> 0.06 | AA20: =VLOOKUP(CONCATENATE(AA6," - ",AA13),Paths!$C$2:$I$28,2,FALSE) -> -0.08 | AB20: =VLOOKUP(CONCATENATE(AB6," - ",AB13),Paths!$C$2:$I$28,2,FALSE) -> -0.04 | AC20: =VLOOKUP(CONCATENATE(AC6," - ",AC13),Paths!$C$2:$I$28,2,FALSE) -> 0.08
W21: 2nd Segment Bonus | X21: =VLOOKUP(CONCATENATE(X$6," - ",X$13),Paths!$C$2:$I$28,3,FALSE) -> 0.05 | Y21: =VLOOKUP(CONCATENATE(Y$6," - ",Y$13),Paths!$C$2:$I$28,3,FALSE) -> -0.07 | Z21: =VLOOKUP(CONCATENATE(Z$6," - ",Z$13),Paths!$C$2:$I$28,3,FALSE) -> 0.07 | AA21: =VLOOKUP(CONCATENATE(AA$6," - ",AA$13),Paths!$C$2:$I$28,3,FALSE) -> -0.09 | AB21: =VLOOKUP(CONCATENATE(AB$6," - ",AB$13),Paths!$C$2:$I$28,3,FALSE) -> -0.05 | AC21: =VLOOKUP(CONCATENATE(AC$6," - ",AC$13),Paths!$C$2:$I$28,3,FALSE) -> 0.09
L22: Source | N22: Type | Q22: Round Start | R22: Round End | S22: Change | W22: 3rd Segment Bonus | X22: =VLOOKUP(CONCATENATE(X$6," - ",X$13),Paths!$C$2:$I$28,4,FALSE) -> 0.06 | Y22: =VLOOKUP(CONCATENATE(Y$6," - ",Y$13),Paths!$C$2:$I$28,4,FALSE) -> -0.08 | Z22: =VLOOKUP(CONCATENATE(Z$6," - ",Z$13),Paths!$C$2:$I$28,4,FALSE) -> 0.08 | AA22: =VLOOKUP(CONCATENATE(AA$6," - ",AA$13),Paths!$C$2:$I$28,4,FALSE) -> -0.1 | AB22: =VLOOKUP(CONCATENATE(AB$6," - ",AB$13),Paths!$C$2:$I$28,4,FALSE) -> -0.06 | AC22: =VLOOKUP(CONCATENATE(AC$6," - ",AC$13),Paths!$C$2:$I$28,4,FALSE) -> 0.1
L23: ='Combatant info data'!V6 | N23: ='Combatant info data'!W6 | Q23: ='Combatant info data'!X6 | R23: ='Combatant info data'!Y6 | S23: ='Combatant info data'!Z6 | W23: 4th Segment Bonus | X23: =VLOOKUP(CONCATENATE(X$6," - ",X$13),Paths!$C$2:$I$28,5,FALSE) -> 0.07 | Y23: =VLOOKUP(CONCATENATE(Y$6," - ",Y$13),Paths!$C$2:$I$28,5,FALSE) -> -0.09 | Z23: =VLOOKUP(CONCATENATE(Z$6," - ",Z$13),Paths!$C$2:$I$28,5,FALSE) -> 0.09 | AA23: =VLOOKUP(CONCATENATE(AA$6," - ",AA$13),Paths!$C$2:$I$28,5,FALSE) -> -0.11 | AB23: =VLOOKUP(CONCATENATE(AB$6," - ",AB$13),Paths!$C$2:$I$28,5,FALSE) -> -0.07 | AC23: =VLOOKUP(CONCATENATE(AC$6," - ",AC$13),Paths!$C$2:$I$28,5,FALSE) -> 0.11
L24: ='Combatant info data'!V7 | N24: ='Combatant info data'!W7 | Q24: ='Combatant info data'!X7 | R24: ='Combatant info data'!Y7 | S24: ='Combatant info data'!Z7 | W24: 5th Segment Bonus | X24: =VLOOKUP(CONCATENATE(X$6," - ",X$13),Paths!$C$2:$I$28,6,FALSE) -> 0.08 | Y24: =VLOOKUP(CONCATENATE(Y$6," - ",Y$13),Paths!$C$2:$I$28,6,FALSE) -> -0.1 | Z24: =VLOOKUP(CONCATENATE(Z$6," - ",Z$13),Paths!$C$2:$I$28,6,FALSE) -> 0.1 | AA24: =VLOOKUP(CONCATENATE(AA$6," - ",AA$13),Paths!$C$2:$I$28,6,FALSE) -> -0.12 | AB24: =VLOOKUP(CONCATENATE(AB$6," - ",AB$13),Paths!$C$2:$I$28,6,FALSE) -> -0.08 | AC24: =VLOOKUP(CONCATENATE(AC$6," - ",AC$13),Paths!$C$2:$I$28,6,FALSE) -> 0.12
L25: ='Combatant info data'!V8 | N25: ='Combatant info data'!W8 | Q25: ='Combatant info data'!X8 | R25: ='Combatant info data'!Y8 | S25: ='Combatant info data'!Z8 | W25: 6th Segment Bonus | X25: =VLOOKUP(CONCATENATE(X$6," - ",X$13),Paths!$C$2:$I$28,7,FALSE) -> 0.09 | Y25: =VLOOKUP(CONCATENATE(Y$6," - ",Y$13),Paths!$C$2:$I$28,7,FALSE) -> -0.11 | Z25: =VLOOKUP(CONCATENATE(Z$6," - ",Z$13),Paths!$C$2:$I$28,7,FALSE) -> 0.11 | AA25: =VLOOKUP(CONCATENATE(AA$6," - ",AA$13),Paths!$C$2:$I$28,7,FALSE) -> -0.13 | AB25: =VLOOKUP(CONCATENATE(AB$6," - ",AB$13),Paths!$C$2:$I$28,7,FALSE) -> -0.09 | AC25: =VLOOKUP(CONCATENATE(AC$6," - ",AC$13),Paths!$C$2:$I$28,7,FALSE) -> 0.13
L26: ='Combatant info data'!V9 | N26: ='Combatant info data'!W9 | Q26: ='Combatant info data'!X9 | R26: ='Combatant info data'!Y9 | S26: ='Combatant info data'!Z9
L27: ='Combatant info data'!V10 | N27: ='Combatant info data'!W10 | Q27: ='Combatant info data'!X10 | R27: ='Combatant info data'!Y10 | S27: ='Combatant info data'!Z10 | W27: Other Bonuses
L28: ='Combatant info data'!V11 | N28: ='Combatant info data'!W11 | Q28: ='Combatant info data'!X11 | R28: ='Combatant info data'!Y11 | S28: ='Combatant info data'!Z11 | W28: Energy Accumulation Bonus | X28: =VLOOKUP(X13,Paths!$P$2:$S$5,3,FALSE) -> 0 | Y28: =VLOOKUP(Y13,Paths!$P$2:$S$5,3,FALSE) -> 0 | Z28: =VLOOKUP(Z13,Paths!$P$2:$S$5,3,FALSE) -> 0 | AA28: =VLOOKUP(AA13,Paths!$P$2:$S$5,3,FALSE) -> 0 | AB28: =VLOOKUP(AB13,Paths!$P$2:$S$5,3,FALSE) -> 0 | AC28: =VLOOKUP(AC13,Paths!$P$2:$S$5,3,FALSE) -> 0
L29: ='Combatant info data'!V12 | N29: ='Combatant info data'!W12 | Q29: ='Combatant info data'!X12 | R29: ='Combatant info data'!Y12 | S29: ='Combatant info data'!Z12 | W29: Starting Energy Segements | X29: =VLOOKUP(X13,Paths!$P$2:$S$5,4,FALSE) -> 0 | Y29: =VLOOKUP(Y13,Paths!$P$2:$S$5,4,FALSE) -> 0 | Z29: =VLOOKUP(Z13,Paths!$P$2:$S$5,4,FALSE) -> 0 | AA29: =VLOOKUP(AA13,Paths!$P$2:$S$5,4,FALSE) -> 0 | AB29: =VLOOKUP(AB13,Paths!$P$2:$S$5,4,FALSE) -> 0 | AC29: =VLOOKUP(AC13,Paths!$P$2:$S$5,4,FALSE) -> 0
W31: Prime Special
W32: Segment Requirements | Y32: Result
W33: Minimum | X33: Maximum | Y33: Power Amplification | AB33: Defense Constraint
W34: =VLOOKUP(W4,'Special Techniques'!$A$2:$E$7,4,FALSE) -> 1 | X34: =VLOOKUP(W4,'Special Techniques'!$A$2:$E$7,5,FALSE) -> 5 | Y34: +10% per segment used | AB34: =VLOOKUP(W4,'Special Techniques'!A2:H7,7,FALSE) -> Block

Sheet Character Sheet - P3
B2: Character Info | K2: Reaction Skills | V2: Path Information
C4: Name | E4: Degree | G4: Rank | L4: Block | W4: Shadow | X4: =VLOOKUP(W4,Paths!$K$2:$N$7,4,FALSE) -> Focuses outward, reducing the chance to successfully parry an attack.
C5: Joe | E5: ='Combatant Information'!D3 -> 1st | G5: ='Combatant Information'!E3 -> Stone | L5: Rank | M5: XP | N5: Next Rank | O5: Success Rate | P5: Successful Damage Mitigation | R5: Unsuccessful Damage Mitigation
C6: Team Name | E6: =Input!I11 -> The Barrels | L6: =IF(M6>='Reaction Progression & Log'!$B$12,'Reaction Progression & Log'!$A$12,IF(M6>='Reaction Progression & Log'!$B$11,'Reaction Progression & Log'!$A$11,IF(M6>='Reaction Progression & Log'!$B$10,'Reaction Progression & Log'!$A$10,IF(M6>='Reaction Progression & Log'!$B$9,'Reaction Progression & Log'!$A$9,IF(M6>='Reaction Progression & Log'!$B$8,'Reaction Progression & Log'!$A$8,IF(M6>='Reaction Progression & Log'!$B$7,'Reaction Progression & Log'!$A$7,IF(M6>='Reaction Progression & Log'!$B$6,'Reaction Progression & Log'!$A$6,IF(M6>='Reaction Progression & Log'!$B$5,'Reaction Progression & Log'!$A$5,IF(M6>='Reaction Progression & Log'!$B$4,'Reaction Progression & Log'!$A$4,IF(M6>='Reaction Progression & Log'!$B$3,'Reaction Progression & Log'!$A$3,'Reaction Progression & Log'!$A$2)))))))))) -> 1 | M6: =SUMIF('Reaction Progression & Log'!$D:$D,$C$5,'Reaction Progression & Log'!$E:$E) -> 2 | N6: =IF(L6=11,"--",VLOOKUP(L6+1,'Reaction Progression & Log'!$A$2:$B$12,2,FALSE)) -> 100 | O6: =VLOOKUP($L6,'Defense Simulations'!$C$3:$W$13,3,FALSE) -> 0.4 | P6: =VLOOKUP($L6,'Defense Simulations'!$C$3:$W$13,4,FALSE) -> 0.55 | R6: =VLOOKUP($L6,'Defense Simulations'!$C$3:$W$13,5,FALSE) -> 0.4 | X6: Fire | Y6: Water | Z6: Air | AA6: Earth | AB6: Shadow | AC6: Light
L7: Current | O7: =Math!J15 -> 0.4 | P7: =Math!L15 -> 0.55 | R7: =Math!N15 -> 0.4
W8: Attunement
B9: Core Training Attributes | L9: Dodge | W9: Selection | X9: FALSE | Y9: FALSE | Z9: FALSE | AA9: FALSE | AB9: TRUE | AC9: FALSE
L10: Rank | M10: XP | N10: Next Rank | O10: Success Rate | P10: Successful Damage Mitigation | R10: Unsuccessful Damage Mitigation | X10: =IF(X9=TRUE,X6,"") | Y10: =IF(Y9=TRUE,Y6,"") | Z10: =IF(Z9=TRUE,Z6,"") | AA10: =IF(AA9=TRUE,AA6,"") | AB10: =IF(AB9=TRUE,AB6,"") -> Shadow | AC10: =IF(AC9=TRUE,AC6,"")
D11: Available CT Points | F11: Stamina | G11: Power | H11: Speed | L11: =IF(M11>='Reaction Progression & Log'!$B$12,'Reaction Progression & Log'!$A$12,IF(M11>='Reaction Progression & Log'!$B$11,'Reaction Progression & Log'!$A$11,IF(M11>='Reaction Progression & Log'!$B$10,'Reaction Progression & Log'!$A$10,IF(M11>='Reaction Progression & Log'!$B$9,'Reaction Progression & Log'!$A$9,IF(M11>='Reaction Progression & Log'!$B$8,'Reaction Progression & Log'!$A$8,IF(M11>='Reaction Progression & Log'!$B$7,'Reaction Progression & Log'!$A$7,IF(M11>='Reaction Progression & Log'!$B$6,'Reaction Progression & Log'!$A$6,IF(M11>='Reaction Progression & Log'!$B$5,'Reaction Progression & Log'!$A$5,IF(M11>='Reaction Progression & Log'!$B$4,'Reaction Progression & Log'!$A$4,IF(M11>='Reaction Progression & Log'!$B$3,'Reaction Progression & Log'!$A$3,'Reaction Progression & Log'!$A$2)))))))))) -> 1 | M11: =SUMIF('Reaction Progression & Log'!$D:$D,$C$5,'Reaction Progression & Log'!$F:$F) -> 0 | N11: =IF(L11=11,"--",VLOOKUP(L11+1,'Reaction Progression & Log'!$A$2:$B$12,2,FALSE)) -> 100 | O11: =VLOOKUP($L11,'Defense Simulations'!$C$3:$W$13,11,FALSE) -> 0.3 | P11: =VLOOKUP($L11,'Defense Simulations'!$C$3:$W$13,12,FALSE) -> 0.8 | R11: =VLOOKUP($L11,'Defense Simulations'!$C$3:$W$13,13,FALSE) -> 0.1 | W11: Progression
C12: Baseline | D12: =VLOOKUP(CONCATENATE(E5," Degree ",G5),'Rank Progression'!C:G,3,FALSE)-(F13+G13+H13) -> 0 | F12: 5 | G12: 5 | H12: 5 | L12: Current | O12: =Math!P15 -> 0.3 | P12: =Math!R15 -> 0.8 | R12: =Math!T15 -> 0.1 | W12: Energy Accumulation | X12: =CONCATENATE(Paths!AE5," / ",VLOOKUP(X13+1,Paths!$P$2:$S$6,2,FALSE)) -> 6 / 35 | Y12: =CONCATENATE(Paths!AG5," / ",VLOOKUP(Y13+1,Paths!$P$2:$S$6,2,FALSE)) -> 0 / 35 | Z12: =CONCATENATE(Paths!AI5," / ",VLOOKUP(Z13+1,Paths!$P$2:$S$6,2,FALSE)) -> 0 / 35 | AA12: =CONCATENATE(Paths!AK5," / ",VLOOKUP(AA13+1,Paths!$P$2:$S$6,2,FALSE)) -> 0.75 / 35 | AB12: =CONCATENATE(Paths!AM5," / ",VLOOKUP(AB13+1,Paths!$P$2:$S$6,2,FALSE)) -> 5.5 / 35 | AC12: =CONCATENATE(Paths!AO5," / ",VLOOKUP(AC13+1,Paths!$P$2:$S$6,2,FALSE)) -> 0 / 35
C13: CT Points | W13: Ascension Gems | X13: =Paths!AF5 -> 0 | Y13: =Paths!AH5 -> 0 | Z13: =Paths!AJ5 -> 0 | AA13: =Paths!AL5 -> 0 | AB13: =Paths!AN5 -> 0 | AC13: =Paths!AP5 -> 0
C14: Current | F14: =F12+F13 -> 5 | G14: =G12+G13 -> 5 | H14: =H12+H13 -> 5 | L14: Parry
L15: Rank | M15: XP | N15: Next Rank | O15: Success Rate | P15: Successful Damage Mitigation | R15: Unsuccessful Damage Mitigation | W15: Style
L16: =IF(M16>='Reaction Progression & Log'!$B$12,'Reaction Progression & Log'!$A$12,IF(M16>='Reaction Progression & Log'!$B$11,'Reaction Progression & Log'!$A$11,IF(M16>='Reaction Progression & Log'!$B$10,'Reaction Progression & Log'!$A$10,IF(M16>='Reaction Progression & Log'!$B$9,'Reaction Progression & Log'!$A$9,IF(M16>='Reaction Progression & Log'!$B$8,'Reaction Progression & Log'!$A$8,IF(M16>='Reaction Progression & Log'!$B$7,'Reaction Progression & Log'!$A$7,IF(M16>='Reaction Progression & Log'!$B$6,'Reaction Progression & Log'!$A$6,IF(M16>='Reaction Progression & Log'!$B$5,'Reaction Progression & Log'!$A$5,IF(M16>='Reaction Progression & Log'!$B$4,'Reaction Progression & Log'!$A$4,IF(M16>='Reaction Progression & Log'!$B$3,'Reaction Progression & Log'!$A$3,'Reaction Progression & Log'!$A$2)))))))))) -> 1 | M16: =SUMIF('Reaction Progression & Log'!$D:$D,$C$5,'Reaction Progression & Log'!$G:$G) -> 8 | N16: =IF(L16=11,"--",VLOOKUP(L16+1,'Reaction Progression & Log'!$A$2:$B$12,2,FALSE)) -> 100 | O16: =VLOOKUP($L16,'Defense Simulations'!$C$3:$W$13,19,FALSE) -> 0.1 | P16: =VLOOKUP($L16,'Defense Simulations'!$C$3:$W$13,20,FALSE) -> 0.9 | R16: =VLOOKUP($L16,'Defense Simulations'!$C$3:$W$13,21,FALSE) -> 0 | W16: Style Focus | X16: Reaction | Y16: Action | Z16: Reaction | AA16: Action | AB16: Action | AC16: Reaction
B17: Personality | L17: Current | O17: =Math!V15 -> 0.1 | P17: =Math!X15 -> 0.9 | R17: =Math!Z15 -> 0 | W17: Energy Focus | X17: Parry S.R. | Y17: Dodge S.R. | Z17: Dodge S.R. | AA17: Block S.R. | AB17: Parry S.R. | AC17: Block S.R.
C19: =Personality!B3 -> Patience | D19: =Personality!C3 -> Empathy | E19: =Personality!D3 -> Cunning | F19: =Personality!E3 -> Logic | G19: =Personality!F3 -> Kindness | H19: =Personality!G3 -> Charisma | W19: Segment Bonuses
C20: =Personality!B6 -> 0.15 | D20: =Personality!C6 -> 0.15 | E20: =Personality!D6 -> 0.19 | F20: =Personality!E6 -> 0.16 | G20: =Personality!F6 -> 0.16 | H20: =Personality!G6 -> 0.19 | K20: Buffs / Debuffs | W20: 1st Segment Bonus | X20: =VLOOKUP(CONCATENATE(X$6," - ",X$13),Paths!$C$2:$I$28,2,FALSE) -> 0.04 | Y20: =VLOOKUP(CONCATENATE(Y6," - ",Y13),Paths!$C$2:$I$28,2,FALSE) -> -0.06 | Z20: =VLOOKUP(CONCATENATE(Z6," - ",Z13),Paths!$C$2:$I$28,2,FALSE) -> 0.06 | AA20: =VLOOKUP(CONCATENATE(AA6," - ",AA13),Paths!$C$2:$I$28,2,FALSE) -> -0.08 | AB20: =VLOOKUP(CONCATENATE(AB6," - ",AB13),Paths!$C$2:$I$28,2,FALSE) -> -0.04 | AC20: =VLOOKUP(CONCATENATE(AC6," - ",AC13),Paths!$C$2:$I$28,2,FALSE) -> 0.08
W21: 2nd Segment Bonus | X21: =VLOOKUP(CONCATENATE(X$6," - ",X$13),Paths!$C$2:$I$28,3,FALSE) -> 0.05 | Y21: =VLOOKUP(CONCATENATE(Y$6," - ",Y$13),Paths!$C$2:$I$28,3,FALSE) -> -0.07 | Z21: =VLOOKUP(CONCATENATE(Z$6," - ",Z$13),Paths!$C$2:$I$28,3,FALSE) -> 0.07 | AA21: =VLOOKUP(CONCATENATE(AA$6," - ",AA$13),Paths!$C$2:$I$28,3,FALSE) -> -0.09 | AB21: =VLOOKUP(CONCATENATE(AB$6," - ",AB$13),Paths!$C$2:$I$28,3,FALSE) -> -0.05 | AC21: =VLOOKUP(CONCATENATE(AC$6," - ",AC$13),Paths!$C$2:$I$28,3,FALSE) -> 0.09
L22: Source | N22: Type | Q22: Round Start | R22: Round End | S22: Change | W22: 3rd Segment Bonus | X22: =VLOOKUP(CONCATENATE(X$6," - ",X$13),Paths!$C$2:$I$28,4,FALSE) -> 0.06 | Y22: =VLOOKUP(CONCATENATE(Y$6," - ",Y$13),Paths!$C$2:$I$28,4,FALSE) -> -0.08 | Z22: =VLOOKUP(CONCATENATE(Z$6," - ",Z$13),Paths!$C$2:$I$28,4,FALSE) -> 0.08 | AA22: =VLOOKUP(CONCATENATE(AA$6," - ",AA$13),Paths!$C$2:$I$28,4,FALSE) -> -0.1 | AB22: =VLOOKUP(CONCATENATE(AB$6," - ",AB$13),Paths!$C$2:$I$28,4,FALSE) -> -0.06 | AC22: =VLOOKUP(CONCATENATE(AC$6," - ",AC$13),Paths!$C$2:$I$28,4,FALSE) -> 0.1
L23: ='Combatant info data'!AF6 | N23: ='Combatant info data'!AG6 | Q23: ='Combatant info data'!AH6 | R23: ='Combatant info data'!AI6 | S23: ='Combatant info data'!AJ6 | W23: 4th Segment Bonus | X23: =VLOOKUP(CONCATENATE(X$6," - ",X$13),Paths!$C$2:$I$28,5,FALSE) -> 0.07 | Y23: =VLOOKUP(CONCATENATE(Y$6," - ",Y$13),Paths!$C$2:$I$28,5,FALSE) -> -0.09 | Z23: =VLOOKUP(CONCATENATE(Z$6," - ",Z$13),Paths!$C$2:$I$28,5,FALSE) -> 0.09 | AA23: =VLOOKUP(CONCATENATE(AA$6," - ",AA$13),Paths!$C$2:$I$28,5,FALSE) -> -0.11 | AB23: =VLOOKUP(CONCATENATE(AB$6," - ",AB$13),Paths!$C$2:$I$28,5,FALSE) -> -0.07 | AC23: =VLOOKUP(CONCATENATE(AC$6," - ",AC$13),Paths!$C$2:$I$28,5,FALSE) -> 0.11
L24: ='Combatant info data'!AF7 | N24: ='Combatant info data'!AG7 | Q24: ='Combatant info data'!AH7 | R24: ='Combatant info data'!AI7 | S24: ='Combatant info data'!AJ7 | W24: 5th Segment Bonus | X24: =VLOOKUP(CONCATENATE(X$6," - ",X$13),Paths!$C$2:$I$28,6,FALSE) -> 0.08 | Y24: =VLOOKUP(CONCATENATE(Y$6," - ",Y$13),Paths!$C$2:$I$28,6,FALSE) -> -0.1 | Z24: =VLOOKUP(CONCATENATE(Z$6," - ",Z$13),Paths!$C$2:$I$28,6,FALSE) -> 0.1 | AA24: =VLOOKUP(CONCATENATE(AA$6," - ",AA$13),Paths!$C$2:$I$28,6,FALSE) -> -0.12 | AB24: =VLOOKUP(CONCATENATE(AB$6," - ",AB$13),Paths!$C$2:$I$28,6,FALSE) -> -0.08 | AC24: =VLOOKUP(CONCATENATE(AC$6," - ",AC$13),Paths!$C$2:$I$28,6,FALSE) -> 0.12
L25: ='Combatant info data'!AF8 | N25: ='Combatant info data'!AG8 | Q25: ='Combatant info data'!AH8 | R25: ='Combatant info data'!AI8 | S25: ='Combatant info data'!AJ8 | W25: 6th Segment Bonus | X25: =VLOOKUP(CONCATENATE(X$6," - ",X$13),Paths!$C$2:$I$28,7,FALSE) -> 0.09 | Y25: =VLOOKUP(CONCATENATE(Y$6," - ",Y$13),Paths!$C$2:$I$28,7,FALSE) -> -0.11 | Z25: =VLOOKUP(CONCATENATE(Z$6," - ",Z$13),Paths!$C$2:$I$28,7,FALSE) -> 0.11 | AA25: =VLOOKUP(CONCATENATE(AA$6," - ",AA$13),Paths!$C$2:$I$28,7,FALSE) -> -0.13 | AB25: =VLOOKUP(CONCATENATE(AB$6," - ",AB$13),Paths!$C$2:$I$28,7,FALSE) -> -0.09 | AC25: =VLOOKUP(CONCATENATE(AC$6," - ",AC$13),Paths!$C$2:$I$28,7,FALSE) -> 0.13
L26: ='Combatant info data'!AF9 | N26: ='Combatant info data'!AG9 | Q26: ='Combatant info data'!AH9 | R26: ='Combatant info data'!AI9 | S26: ='Combatant info data'!AJ9
L27: ='Combatant info data'!AF10 | N27: ='Combatant info data'!AG10 | Q27: ='Combatant info data'!AH10 | R27: ='Combatant info data'!AI10 | S27: ='Combatant info data'!AJ10 | W27: Other Bonuses
L28: ='Combatant info data'!AF11 | N28: ='Combatant info data'!AG11 | Q28: ='Combatant info data'!AH11 | R28: ='Combatant info data'!AI11 | S28: ='Combatant info data'!AJ11 | W28: Energy Accumulation Bonus | X28: =VLOOKUP(X13,Paths!$P$2:$S$5,3,FALSE) -> 0 | Y28: =VLOOKUP(Y13,Paths!$P$2:$S$5,3,FALSE) -> 0 | Z28: =VLOOKUP(Z13,Paths!$P$2:$S$5,3,FALSE) -> 0 | AA28: =VLOOKUP(AA13,Paths!$P$2:$S$5,3,FALSE) -> 0 | AB28: =VLOOKUP(AB13,Paths!$P$2:$S$5,3,FALSE) -> 0 | AC28: =VLOOKUP(AC13,Paths!$P$2:$S$5,3,FALSE) -> 0
L29: ='Combatant info data'!AF12 | N29: ='Combatant info data'!AG12 | Q29: ='Combatant info data'!AH12 | R29: ='Combatant info data'!AI12 | S29: ='Combatant info data'!AJ12 | W29: Starting Energy Segements | X29: =VLOOKUP(X13,Paths!$P$2:$S$5,4,FALSE) -> 0 | Y29: =VLOOKUP(Y13,Paths!$P$2:$S$5,4,FALSE) -> 0 | Z29: =VLOOKUP(Z13,Paths!$P$2:$S$5,4,FALSE) -> 0 | AA29: =VLOOKUP(AA13,Paths!$P$2:$S$5,4,FALSE) -> 0 | AB29: =VLOOKUP(AB13,Paths!$P$2:$S$5,4,FALSE) -> 0 | AC29: =VLOOKUP(AC13,Paths!$P$2:$S$5,4,FALSE) -> 0
W31: Prime Special
W32: Segment Requirements | Y32: Result
W33: Minimum | X33: Maximum | Y33: Power Amplification | AB33: Defense Constraint
W34: =VLOOKUP(W4,'Special Techniques'!$A$2:$E$7,4,FALSE) -> 1 | X34: =VLOOKUP(W4,'Special Techniques'!$A$2:$E$7,5,FALSE) -> 5 | Y34: +10% per segment used | AB34: =VLOOKUP(W4,'Special Techniques'!A2:H7,7,FALSE) -> Parry

Sheet Input
A1: Combatant Information | L1: Reaction List | M1: Available Reactions
A2: Combatant | B2: Degree | C2: Rank | D2: Path | E2: Stamina | F2: Power | G2: Speed | H2: Block Rank | I2: Dodge Rank | J2: Parry Rank | K2: Path Ascension Level | L2: Block | M2: =IF($L$7="Special",IF(VLOOKUP(VLOOKUP($M$7,$A$3:$D$8,4,FALSE),'Special Techniques'!$A$2:$G$7,7,FALSE)=L2,L2,""),IF($L$7="K.O.","",IF($L$7="Blindside","",L2))) -> #N/A | N2: This will be based off subtypes defense constraints eventually
A3: ='Character Sheet - P1'!C5 -> Will | B3: =VLOOKUP(Math!A57,'Rank Progression'!$D$2:$Q$101,14,FALSE) -> 1st | C3: =VLOOKUP(Math!A57,'Rank Progression'!$D$2:$Q$101,13,FALSE) -> Stone | D3: ='Character Sheet - P1'!W4 -> Air | E3: ='Character Sheet - P1'!F14 -> 5 | F3: ='Character Sheet - P1'!G14 -> 5 | G3: ='Character Sheet - P1'!H14 -> 5 | H3: ='Character Sheet - P1'!L6 -> 1 | I3: ='Character Sheet - P1'!L11 -> 1 | J3: ='Character Sheet - P1'!L16 -> 1 | K3: =IF(D3=Paths!$AE$1,Paths!AF$3,IF(D3=Paths!$AG$1,Paths!AH3,IF(D3=Paths!$AI$1,Paths!AJ3,IF(D3=Paths!$AK$1,Paths!AL3,IF(D3=Paths!$AM$1,Paths!AN3,IF(D3=Paths!$AO$1,Paths!AP3,"X")))))) -> 0 | L3: Dodge | M3: =IF($L$7="Special",IF(VLOOKUP(VLOOKUP($M$7,$A$3:$D$8,4,FALSE),'Special Techniques'!$A$2:$G$7,7,FALSE)=L3,L3,""),IF($L$7="K.O.","",IF($L$7="Blindside","",L3))) -> #N/A
A4: ='Character Sheet - P2'!C5 -> Carter | B4: =B3 -> 1st | C4: =C3 -> Stone | D4: ='Character Sheet - P2'!W4 -> Earth | E4: ='Character Sheet - P2'!F14 -> 5 | F4: ='Character Sheet - P2'!G14 -> 5 | G4: ='Character Sheet - P2'!H14 -> 5 | H4: ='Character Sheet - P2'!L6 -> 1 | I4: ='Character Sheet - P2'!L11 -> 1 | J4: ='Character Sheet - P2'!L16 -> 1 | K4: =IF(D4=Paths!$AE$1,Paths!AF$3,IF(D4=Paths!$AG$1,Paths!AH4,IF(D4=Paths!$AI$1,Paths!AJ4,IF(D4=Paths!$AK$1,Paths!AL4,IF(D4=Paths!$AM$1,Paths!AN4,IF(D4=Paths!$AO$1,Paths!AP4,"X")))))) -> 0 | L4: Parry | M4: =IF($L$7="Special",IF(VLOOKUP(VLOOKUP($M$7,$A$3:$D$8,4,FALSE),'Special Techniques'!$A$2:$G$7,7,FALSE)=L4,L4,""),IF($L$7="K.O.","",IF($L$7="Blindside","",L4))) -> #N/A
A5: ='Character Sheet - P3'!C5 -> Joe | B5: =B3 -> 1st | C5: =C3 -> Stone | D5: ='Character Sheet - P3'!W4 -> Shadow | E5: ='Character Sheet - P3'!F14 -> 5 | F5: ='Character Sheet - P3'!G14 -> 5 | G5: ='Character Sheet - P3'!H14 -> 5 | H5: ='Character Sheet - P3'!L6 -> 1 | I5: ='Character Sheet - P3'!L11 -> 1 | J5: ='Character Sheet - P3'!L16 -> 1 | K5: =IF(D5=Paths!$AE$1,Paths!AF$3,IF(D5=Paths!$AG$1,Paths!AH5,IF(D5=Paths!$AI$1,Paths!AJ5,IF(D5=Paths!$AK$1,Paths!AL5,IF(D5=Paths!$AM$1,Paths!AN5,IF(D5=Paths!$AO$1,Paths!AP5,"X")))))) -> 0 | L5: Defenseless | M5: =IF($L$7="Blindside",L5,IF(L7="K.O.",L5,"")) -> #N/A | X5: Initial Combat Path | Y5: Attuned Paths
A6: =VLOOKUP(J11,'Battle Scenarios'!A:Z,5,FALSE) -> Jake | B6: =VLOOKUP(J11,'Battle Scenarios'!A:Z,3,FALSE) -> 1st | C6: =VLOOKUP(J11,'Battle Scenarios'!A:Z,4,FALSE) -> Stone | D6: Earth | E6: =VLOOKUP(CONCATENATE($I$14," - ", $A6),'Battle Scenarios'!$F$2:$Y$1000,2,FALSE) -> 5 | F6: =VLOOKUP(CONCATENATE($I$14," - ", $A6),'Battle Scenarios'!$F$2:$Y$1000,3,FALSE) -> 5 | G6: =VLOOKUP(CONCATENATE($I$14," - ", $A6),'Battle Scenarios'!$F$2:$Y$1000,4,FALSE) -> 5 | H6: =VLOOKUP(CONCATENATE($I$14," - ", $A6),'Battle Scenarios'!$F$2:$Y$1000,5,FALSE) -> 1 | I6: =VLOOKUP(CONCATENATE($I$14," - ", $A6),'Battle Scenarios'!$F$2:$Y$1000,6,FALSE) -> 1 | J6: =VLOOKUP(CONCATENATE($I$14," - ", $A6),'Battle Scenarios'!$F$2:$Y$1000,7,FALSE) -> 1 | K6: =VLOOKUP(CONCATENATE($I$14," - ", $A6),'Battle Scenarios'!$F$2:$Y$1000,8+K10,FALSE) -> 0 | L6: Current Action | M6: Current Actor | N6: Current Rank Roll | Q6: Current Actor Path | R6: Target Path | X6: =VLOOKUP($J$11,'Battle Scenarios'!$A:$AG,25,FALSE) -> Earth | Y6: =VLOOKUP($J$11,'Battle Scenarios'!$A:$AG,28,FALSE) | Z6: =VLOOKUP($J$11,'Battle Scenarios'!$A:$AG,29,FALSE) | AA6: =VLOOKUP($J$11,'Battle Scenarios'!$A:$AG,30,FALSE) | AB6: =VLOOKUP($J$11,'Battle Scenarios'!$A:$AG,31,FALSE) -> Earth | AC6: =VLOOKUP($J$11,'Battle Scenarios'!$A:$AG,32,FALSE) | AD6: =VLOOKUP($J$11,'Battle Scenarios'!$A:$AG,33,FALSE)
A7: =VLOOKUP(J11,'Battle Scenarios'!A:AI,34,FALSE) -> Jim | B7: =B6 -> 1st | C7: =C6 -> Stone | D7: Earth | E7: =VLOOKUP(CONCATENATE($I$14," - ", $A7),'Battle Scenarios'!$F$2:$Y$1000,2,FALSE) -> 5 | F7: =VLOOKUP(CONCATENATE($I$14," - ", $A7),'Battle Scenarios'!$F$2:$Y$1000,3,FALSE) -> 5 | G7: =VLOOKUP(CONCATENATE($I$14," - ", $A7),'Battle Scenarios'!$F$2:$Y$1000,4,FALSE) -> 5 | H7: =VLOOKUP(CONCATENATE($I$14," - ", $A7),'Battle Scenarios'!$F$2:$Y$1000,5,FALSE) -> 1 | I7: =VLOOKUP(CONCATENATE($I$14," - ", $A7),'Battle Scenarios'!$F$2:$Y$1000,6,FALSE) -> 1 | J7: =VLOOKUP(CONCATENATE($I$14," - ", $A7),'Battle Scenarios'!$F$2:$Y$1000,7,FALSE) -> 1 | K7: =VLOOKUP(CONCATENATE($I$14," - ", $A7),'Battle Scenarios'!$F$2:$Y$1000,8+K11,FALSE) -> 0 | L7: {=IF(ISERROR(INDEX(O32:O46,O13-O12,1)),HLOOKUP("*",B32:B46,O13-O12,FALSE),IF(N7=1,"K.O.",IF(INDEX(O32:O46,O13-O12,1)=1,"Blindside",HLOOKUP("*",B32:B46,O13-O12,FALSE))))} -> #N/A | M7: =HLOOKUP("*",B50:B64,O13-O12,FALSE) -> #N/A | N7: {=INDEX(M32:M46,O13-O12,1)} | Q7: =VLOOKUP(M7,$A$3:$D$8,4,FALSE) -> #N/A | R7: =VLOOKUP(HLOOKUP("*",H50:H64,O13-O12,FALSE),$A$3:$D$8,4,FALSE) -> #N/A | X7: =VLOOKUP(CONCATENATE($I$14," - ", $A7),'Battle Scenarios'!$F$2:$Y$1000,20,FALSE) -> Earth | Y7: =VLOOKUP(CONCATENATE($I$14," - ", $A7),'Battle Scenarios'!$F$2:$AG$1000,23,FALSE) | Z7: =VLOOKUP(CONCATENATE($I$14," - ", $A7),'Battle Scenarios'!$F$2:$AG$1000,24,FALSE) | AA7: =VLOOKUP(CONCATENATE($I$14," - ", $A7),'Battle Scenarios'!$F$2:$AG$1000,25,FALSE) | AB7: =VLOOKUP(CONCATENATE($I$14," - ", $A7),'Battle Scenarios'!$F$2:$AG$1000,26,FALSE) -> Earth | AC7: =VLOOKUP(CONCATENATE($I$14," - ", $A7),'Battle Scenarios'!$F$2:$AG$1000,27,FALSE) | AD7: =VLOOKUP(CONCATENATE($I$14," - ", $A7),'Battle Scenarios'!$F$2:$AG$1000,28,FALSE)
A8: =VLOOKUP(J11,'Battle Scenarios'!A:AI,35,FALSE) -> Jordan | B8: =B6 -> 1st | C8: =C6 -> Stone | D8: Earth | E8: =VLOOKUP(CONCATENATE($I$14," - ", $A8),'Battle Scenarios'!$F$2:$Y$1000,2,FALSE) -> 5 | F8: =VLOOKUP(CONCATENATE($I$14," - ", $A8),'Battle Scenarios'!$F$2:$Y$1000,3,FALSE) -> 5 | G8: =VLOOKUP(CONCATENATE($I$14," - ", $A8),'Battle Scenarios'!$F$2:$Y$1000,4,FALSE) -> 5 | H8: =VLOOKUP(CONCATENATE($I$14," - ", $A8),'Battle Scenarios'!$F$2:$Y$1000,5,FALSE) -> 1 | I8: =VLOOKUP(CONCATENATE($I$14," - ", $A8),'Battle Scenarios'!$F$2:$Y$1000,6,FALSE) -> 1 | J8: =VLOOKUP(CONCATENATE($I$14," - ", $A8),'Battle Scenarios'!$F$2:$Y$1000,7,FALSE) -> 1 | K8: =VLOOKUP(CONCATENATE($I$14," - ", $A8),'Battle Scenarios'!$F$2:$Y$1000,8+K12,FALSE) -> 0 | X8: =VLOOKUP(CONCATENATE($I$14," - ", $A8),'Battle Scenarios'!$F$2:$Y$1000,20,FALSE) -> Earth | Y8: =VLOOKUP(CONCATENATE($I$14," - ", $A8),'Battle Scenarios'!$F$2:$AG$1000,23,FALSE) | Z8: =VLOOKUP(CONCATENATE($I$14," - ", $A8),'Battle Scenarios'!$F$2:$AG$1000,24,FALSE) | AA8: =VLOOKUP(CONCATENATE($I$14," - ", $A8),'Battle Scenarios'!$F$2:$AG$1000,25,FALSE) | AB8: =VLOOKUP(CONCATENATE($I$14," - ", $A8),'Battle Scenarios'!$F$2:$AG$1000,26,FALSE) -> Earth | AC8: =VLOOKUP(CONCATENATE($I$14," - ", $A8),'Battle Scenarios'!$F$2:$AG$1000,27,FALSE) | AD8: =VLOOKUP(CONCATENATE($I$14," - ", $A8),'Battle Scenarios'!$F$2:$AG$1000,28,FALSE)
L9: Execution Records
A10: Combatant | B10: Max Stamina | C10: Current Stamina | D10: Current Energy | E10: Current Segments | I10: Team Names | J10: Current Scenario | K10: =IF(D6="Fire",0,IF(D6="Water",1,IF(D6="Air",2,IF(D6="Earth",3,IF(D6="Shadow",4,IF(D6="Light",5,"X")))))) -> 3 | L10: Initial Copy Row | M10: 50 | N10: Initial Copy Row | O10: 50
A11: =A3 -> Will | B11: =Math!B13 -> 25 | C11: =Math!C13 -> 25 | D11: =Math!E22 -> 0 | E11: =Math!F22 -> 0 | I11: The Barrels | J11: 2 | K11: =IF(D7="Fire",0,IF(D7="Water",1,IF(D7="Air",2,IF(D7="Earth",3,IF(D7="Shadow",4,IF(D7="Light",5,"X")))))) -> 3 | L11: Current Copy Row | M11: 50 | N11: Current Copy Row | O11: 50 | X11: Paste Range for champ fight
A12: =A4 -> Carter | B12: =Math!B14 -> 25 | C12: =Math!C14 -> 25 | D12: =Math!E23 -> 0 | E12: =Math!F23 -> 0 | K12: =IF(D8="Fire",0,IF(D8="Water",1,IF(D8="Air",2,IF(D8="Earth",3,IF(D8="Shadow",4,IF(D8="Light",5,"X")))))) -> 3 | L12: Initial Paste Row | M12: 73 | N12: Initial Paste Row | O12: 32 | X12: 1 | Y12: 14 | Z12: Defenseless
A13: =A5 -> Joe | B13: =Math!B15 -> 25 | C13: =Math!C15 -> 25 | D13: =Math!E24 -> 0 | E13: =Math!F24 -> 0 | L13: Current Paste Row | M13: 73 | N13: Current Paste Row | O13: 32 | X13: 1 | Y13: 5 | Z13: Block | AA13: 12 | AB13: 15
A14: =A6 -> Jake | B14: =Math!B16 -> 25 | C14: =Math!C16 -> 25 | D14: =Math!E25 -> 0 | E14: =Math!F25 -> 0 | I14: =VLOOKUP(J11,'Battle Scenarios'!A:Z,2,FALSE) -> Triple J | X14: 1 | Y14: 6 | Z14: Dodge | AA14: 6
A15: =A7 -> Jim | B15: =Math!B17 -> 25 | C15: =Math!C17 -> 25 | D15: =Math!E26 -> 0 | E15: =Math!F26 -> 0 | Z15: Parry | AA15: 12
A16: =A8 -> Jordan | B16: =Math!B18 -> 25 | C16: =Math!C18 -> 25 | D16: =Math!E27 -> 0 | E16: =Math!F27 -> 0 | X16: 1 | Y16: 5 | Z16: Dodge | AA16: 7
Z17: Block | AA17: 9
A18: ROUND | B18: 1 | Z18: Dodge | AA18: 6
A20: Round Prep Phase | G20: Sorted Round Preparation Phase
A21: Actor | B21: Type | C21: Sub Type | D21: Target | E21: Energy Segments Used | G21: Actor | H21: Type | I21: Target | L21: Check for stance display | O21: Target - Action Against Target
A22: =A3 -> Will | B22: Attack | D22: Jake | G22: =Math!J31 -> Will | H22: =Math!K31 -> 0 | I22: =Math!L31 -> 0 | L22: =IF(C11>0,1,0) -> 1 | M22: =IF(ISBLANK(B22),0,1) -> 1 | N22: =IF(L22=0,1,IF(M22=1,1,0)) -> 1 | O22: =CONCATENATE(I22, " - ",H22) -> 0 - 0 | Q22: =G22 -> Will
A23: =A4 -> Carter | G23: =Math!J32 -> Carter | H23: =Math!K32 -> 0 | I23: =Math!L32 -> 0 | L23: =IF(C12>0,1,0) -> 1 | M23: =IF(ISBLANK(B23),0,1) -> 0 | N23: =IF(L23=0,1,IF(M23=1,1,0)) -> 0 | O23: =CONCATENATE(I23, " - ",H23) -> 0 - 0 | Q23: =G23 -> Carter
A24: =A5 -> Joe | G24: =Math!J33 -> Joe | H24: =Math!K33 -> 0 | I24: =Math!L33 -> 0 | L24: =IF(C13>0,1,0) -> 1 | M24: =IF(ISBLANK(B24),0,1) -> 0 | N24: =IF(L24=0,1,IF(M24=1,1,0)) -> 0 | O24: =CONCATENATE(I24, " - ",H24) -> 0 - 0 | Q24: =G24 -> Joe
A25: =A6 -> Jake | G25: =Math!J34 -> Jake | H25: =Math!K34 -> 0 | I25: =Math!L34 -> 0 | L25: =IF(C14>0,1,0) -> 1 | M25: =IF(ISBLANK(B25),0,1) -> 0 | N25: =IF(L25=0,1,IF(M25=1,1,0)) -> 0 | O25: =CONCATENATE(I25, " - ",H25) -> 0 - 0 | Q25: =G25 -> Jake
A26: =A7 -> Jim | G26: =Math!J35 -> Jim | H26: =Math!K35 -> 0 | I26: =Math!L35 -> 0 | L26: =IF(C15>0,1,0) -> 1 | M26: =IF(ISBLANK(B26),0,1) -> 0 | N26: =IF(L26=0,1,IF(M26=1,1,0)) -> 0 | O26: =CONCATENATE(I26, " - ",H26) -> 0 - 0 | Q26: =G26 -> Jim
A27: =A8 -> Jordan | G27: =Math!J36 -> Jordan | H27: =Math!K36 -> 0 | I27: =Math!L36 -> 0 | L27: =IF(C16>0,1,0) -> 1 | M27: =IF(ISBLANK(B27),0,1) -> 0 | N27: =IF(L27=0,1,IF(M27=1,1,0)) -> 0 | O27: =CONCATENATE(I27, " - ",H27) -> 0 - 0 | Q27: =G27 -> Jordan
N28: =SUM(N22:N27) -> 1 | O28: =I28 -> 0
A29: Round Execution Phase
B30: Phase 1 | F30: Phase 2 | G30: Phase 3 | H30: Phase 4 | J30: Phase 5
A31: Actor | B31: Type | C31: Sub Type | D31: Target | E31: Energy Segments Used | F31: Rank Roll | G31: Blindside Roll | H31: Target Defense Action | I31: Defense Roll | J31: Crushing Blow Roll | K31: Is Coppied | L31: Rank KO Math For Formatting | N31: Blindside Math For Formatting | P31: Crushing Blow Math For Formatting | R31: Defense Result for Formatting
L32: =Math!D40 -> 0 | M32: =Math!E40 | N32: =Math!H40 -> 0 | O32: =Math!I40 | P32: =Math!AF40 -> 0 | Q32: =Math!AG40 | R32: =Math!W40 -> 0 | S32: =Math!X40
L33: =Math!D41 -> 0 | M33: =Math!E41 | N33: =Math!H41 -> 0 | O33: =Math!I41 | P33: =Math!AF41 -> 0 | Q33: =Math!AG41 | R33: =Math!W41 -> 0 | S33: =Math!X41
L34: =Math!D42 -> 0 | M34: =Math!E42 | N34: =Math!H42 -> 0 | O34: =Math!I42 | P34: =Math!AF42 -> 0 | Q34: =Math!AG42 | R34: =Math!W42 -> 0 | S34: =Math!X42
L35: =Math!D43 -> 0 | M35: =Math!E43 | N35: =Math!H43 -> 0 | O35: =Math!I43 | P35: =Math!AF43 -> 0 | Q35: =Math!AG43 | R35: =Math!W43 -> 0 | S35: =Math!X43
L36: =Math!D44 -> 0 | M36: =Math!E44 | N36: =Math!H44 -> 0 | O36: =Math!I44 | P36: =Math!AF44 -> 0 | Q36: =Math!AG44 | R36: =Math!W44 -> 0 | S36: =Math!X44
L37: =Math!D45 -> 0 | M37: =Math!E45 | N37: =Math!H45 -> 0 | O37: =Math!I45 | P37: =Math!AF45 -> 0 | Q37: =Math!AG45 | R37: =Math!W45 -> 0 | S37: =Math!X45
L38: =Math!D46 -> 0 | M38: =Math!E46 | N38: =Math!H46 -> 0 | O38: =Math!I46 | P38: =Math!AF46 -> 0 | Q38: =Math!AG46 | R38: =Math!W46 -> 0 | S38: =Math!X46
L39: =Math!D47 -> 0 | M39: =Math!E47 | N39: =Math!H47 -> 0 | O39: =Math!I47 | P39: =Math!AF47 -> 0 | Q39: =Math!AG47 | R39: =Math!W47 -> 0 | S39: =Math!X47
L40: =Math!D48 -> 0 | M40: =Math!E48 | N40: =Math!H48 -> 0 | O40: =Math!I48 | P40: =Math!AF48 -> 0 | Q40: =Math!AG48 | R40: =Math!W48 -> 0 | S40: =Math!X48
L41: =Math!D49 -> 0 | M41: =Math!E49 | N41: =Math!H49 -> 0 | O41: =Math!I49 | P41: =Math!AF49 -> 0 | Q41: =Math!AG49 | R41: =Math!W49 -> 0 | S41: =Math!X49
...

Sheet Rank Progression
A1: Echelon | B1: Degree | C1: Degree Rank | D1: # | E1: Total CTP | K1: Degree Delta | L1: XP Gained | P1: Rank | Q1: Degree | U1: Degree Delta | V1: XP Gained | W1: Database Code
A2: Stone | B2: 1st | C2: =CONCATENATE(B2," Degree ",A2) -> 1st Degree Stone | D2: 1 | E2: 0 | F2: =E2 -> 0 | G2: First | H2: =CONCATENATE("rankDatabase.Add(new RankData(RankEchelon.",SUBSTITUTE(A2," ","_",),", RankDegree.",VLOOKUP(B2,$B$2:$G$11,6,FALSE),", ",TEXT(D2,"0.0"),"f, ",F2,", ",E2,"));") -> #VALUE! | K2: -10 | L2: 10 | P2: =A2 -> Stone | Q2: =B2 -> 1st | U2: =K2/10 -> -1 | V2: =L2 -> 10 | W2: =CONCATENATE("rankXPGainsDatabase.Add(new RankXPGainsData(",U2,"f, ",V2,"));") -> rankXPGainsDatabase.Add(new RankXPGainsData(-1f, 10));
A3: Stone | B3: 2nd | C3: =CONCATENATE(B3," Degree ",A3) -> 2nd Degree Stone | D3: 1.1 | E3: 2 | F3: =E3-E2 -> 2 | G3: Second | H3: =CONCATENATE("rankDatabase.Add(new RankData(RankEchelon.",SUBSTITUTE(A3," ","_",),", RankDegree.",VLOOKUP(B3,$B$2:$G$11,6,FALSE),", ",TEXT(D3,"0.0"),"f, ",F3,", ",E3,"));") -> #VALUE! | K3: -9 | L3: 14 | P3: =A3 -> Stone | Q3: =B3 -> 2nd | U3: =K3/10 -> -0.9 | V3: =L3 -> 14 | W3: =CONCATENATE("rankXPGainsDatabase.Add(new RankXPGainsData(",U3,"f, ",V3,"));") -> rankXPGainsDatabase.Add(new RankXPGainsData(-0.9f, 14));
A4: Stone | B4: 3rd | C4: =CONCATENATE(B4," Degree ",A4) -> 3rd Degree Stone | D4: 1.2 | E4: 4 | F4: =E4-E3 -> 2 | G4: Third | H4: =CONCATENATE("rankDatabase.Add(new RankData(RankEchelon.",SUBSTITUTE(A4," ","_",),", RankDegree.",VLOOKUP(B4,$B$2:$G$11,6,FALSE),", ",TEXT(D4,"0.0"),"f, ",F4,", ",E4,"));") -> #VALUE! | K4: -8 | L4: 18 | P4: =A4 -> Stone | Q4: =B4 -> 3rd | U4: =K4/10 -> -0.8 | V4: =L4 -> 18 | W4: =CONCATENATE("rankXPGainsDatabase.Add(new RankXPGainsData(",U4,"f, ",V4,"));") -> rankXPGainsDatabase.Add(new RankXPGainsData(-0.8f, 18));
A5: Stone | B5: 4th | C5: =CONCATENATE(B5," Degree ",A5) -> 4th Degree Stone | D5: 1.3 | E5: 6 | F5: =E5-E4 -> 2 | G5: Fourth | H5: =CONCATENATE("rankDatabase.Add(new RankData(RankEchelon.",SUBSTITUTE(A5," ","_",),", RankDegree.",VLOOKUP(B5,$B$2:$G$11,6,FALSE),", ",TEXT(D5,"0.0"),"f, ",F5,", ",E5,"));") -> #VALUE! | K5: -7 | L5: 23 | P5: =A5 -> Stone | Q5: =B5 -> 4th | U5: =K5/10 -> -0.7 | V5: =L5 -> 23 | W5: =CONCATENATE("rankXPGainsDatabase.Add(new RankXPGainsData(",U5,"f, ",V5,"));") -> rankXPGainsDatabase.Add(new RankXPGainsData(-0.7f, 23));
A6: Stone | B6: 5th | C6: =CONCATENATE(B6," Degree ",A6) -> 5th Degree Stone | D6: 1.4 | E6: 8 | F6: =E6-E5 -> 2 | G6: Fifth | H6: =CONCATENATE("rankDatabase.Add(new RankData(RankEchelon.",SUBSTITUTE(A6," ","_",),", RankDegree.",VLOOKUP(B6,$B$2:$G$11,6,FALSE),", ",TEXT(D6,"0.0"),"f, ",F6,", ",E6,"));") -> #VALUE! | K6: -6 | L6: 28 | P6: =A6 -> Stone | Q6: =B6 -> 5th | U6: =K6/10 -> -0.6 | V6: =L6 -> 28 | W6: =CONCATENATE("rankXPGainsDatabase.Add(new RankXPGainsData(",U6,"f, ",V6,"));") -> rankXPGainsDatabase.Add(new RankXPGainsData(-0.6f, 28));
A7: Stone | B7: 6th | C7: =CONCATENATE(B7," Degree ",A7) -> 6th Degree Stone | D7: 1.5 | E7: 10 | F7: =E7-E6 -> 2 | G7: Sixth | H7: =CONCATENATE("rankDatabase.Add(new RankData(RankEchelon.",SUBSTITUTE(A7," ","_",),", RankDegree.",VLOOKUP(B7,$B$2:$G$11,6,FALSE),", ",TEXT(D7,"0.0"),"f, ",F7,", ",E7,"));") -> #VALUE! | K7: -5 | L7: 33 | P7: =A7 -> Stone | Q7: =B7 -> 6th | U7: =K7/10 -> -0.5 | V7: =L7 -> 33 | W7: =CONCATENATE("rankXPGainsDatabase.Add(new RankXPGainsData(",U7,"f, ",V7,"));") -> rankXPGainsDatabase.Add(new RankXPGainsData(-0.5f, 33));
A8: Stone | B8: 7th | C8: =CONCATENATE(B8," Degree ",A8) -> 7th Degree Stone | D8: 1.6 | E8: 12 | F8: =E8-E7 -> 2 | G8: Seventh | H8: =CONCATENATE("rankDatabase.Add(new RankData(RankEchelon.",SUBSTITUTE(A8," ","_",),", RankDegree.",VLOOKUP(B8,$B$2:$G$11,6,FALSE),", ",TEXT(D8,"0.0"),"f, ",F8,", ",E8,"));") -> #VALUE! | K8: -4 | L8: 38 | P8: =A8 -> Stone | Q8: =B8 -> 7th | U8: =K8/10 -> -0.4 | V8: =L8 -> 38 | W8: =CONCATENATE("rankXPGainsDatabase.Add(new RankXPGainsData(",U8,"f, ",V8,"));") -> rankXPGainsDatabase.Add(new RankXPGainsData(-0.4f, 38));
A9: Stone | B9: 8th | C9: =CONCATENATE(B9," Degree ",A9) -> 8th Degree Stone | D9: 1.7 | E9: 15 | F9: =E9-E8 -> 3 | G9: Eighth | H9: =CONCATENATE("rankDatabase.Add(new RankData(RankEchelon.",SUBSTITUTE(A9," ","_",),", RankDegree.",VLOOKUP(B9,$B$2:$G$11,6,FALSE),", ",TEXT(D9,"0.0"),"f, ",F9,", ",E9,"));") -> #VALUE! | K9: -3 | L9: 41 | P9: =A9 -> Stone | Q9: =B9 -> 8th | U9: =K9/10 -> -0.3 | V9: =L9 -> 41 | W9: =CONCATENATE("rankXPGainsDatabase.Add(new RankXPGainsData(",U9,"f, ",V9,"));") -> rankXPGainsDatabase.Add(new RankXPGainsData(-0.3f, 41));
A10: Stone | B10: 9th | C10: =CONCATENATE(B10," Degree ",A10) -> 9th Degree Stone | D10: 1.8 | E10: 18 | F10: =E10-E9 -> 3 | G10: Nineth | H10: =CONCATENATE("rankDatabase.Add(new RankData(RankEchelon.",SUBSTITUTE(A10," ","_",),", RankDegree.",VLOOKUP(B10,$B$2:$G$11,6,FALSE),", ",TEXT(D10,"0.0"),"f, ",F10,", ",E10,"));") -> #VALUE! | K10: -2 | L10: 44 | P10: =A10 -> Stone | Q10: =B10 -> 9th | U10: =K10/10 -> -0.2 | V10: =L10 -> 44 | W10: =CONCATENATE("rankXPGainsDatabase.Add(new RankXPGainsData(",U10,"f, ",V10,"));") -> rankXPGainsDatabase.Add(new RankXPGainsData(-0.2f, 44));
A11: Stone | B11: 10th | C11: =CONCATENATE(B11," Degree ",A11) -> 10th Degree Stone | D11: 1.9 | E11: 21 | F11: =E11-E10 -> 3 | G11: Tenth | H11: =CONCATENATE("rankDatabase.Add(new RankData(RankEchelon.",SUBSTITUTE(A11," ","_",),", RankDegree.",VLOOKUP(B11,$B$2:$G$11,6,FALSE),", ",TEXT(D11,"0.0"),"f, ",F11,", ",E11,"));") -> #VALUE! | K11: -1 | L11: 47 | P11: =A11 -> Stone | Q11: =B11 -> 10th | U11: =K11/10 -> -0.1 | V11: =L11 -> 47 | W11: =CONCATENATE("rankXPGainsDatabase.Add(new RankXPGainsData(",U11,"f, ",V11,"));") -> rankXPGainsDatabase.Add(new RankXPGainsData(-0.1f, 47));
